Workbook

Sheet README_notes
A1: Experiment Data Cleaning & Preparation Notes
A3: Sheet order: raw_data -> data_quality_checks -> cleaned_data
A5: 1. raw_data: original dataset as downloaded (1408 rows), with two helper columns added:
A6: - row_fingerprint: concatenation of all 16 fields, used to detect exact duplicate rows
A7: - duplicate_flag: identifies 'Exact Duplicate - Keep First' / 'Exact Duplicate - Remove' / 'Unique'
A9: 2. data_quality_checks: summarizes missing values, duplicate counts, invalid binary values,
A10: group counts, revenue outliers (IQR method), and segment distribution across Control/Treatment.
A12: 3. cleaned_data: final analysis-ready dataset (1400 rows) after:
A13: - Removing 8 exact duplicate rows (kept first occurrence)
A14: - Filling missing device_type (18 rows) and traffic_source (24 rows) with 'Unknown'
A15: - No invalid binary values were found (all 0/1 fields were clean)
A16: - 4 revenue values among converted users were flagged as statistical outliers (IQR method)
... A19: Group sizes after cleaning: Control = 690, Treatment = 710

Sheet raw_data
A1: user_id | B1: signup_date | C1: experiment_group | D1: region | E1: device_type | F1: traffic_source | G1: plan_type | H1: visited_landing_page | I1: started_trial | J1: completed_onboarding | K1: converted_to_paid | L1: revenue_30d | M1: support_tickets_30d | N1: refund_requested | O1: days_to_convert | P1: engagement_score | Q1: row_fingerprint | R1: duplicate_flag
A2: USR-100001 | B2: 45732 | C2: Control | D2: North | E2: Desktop | F2: Email | G2: Basic | H2: 0 | I2: 0 | J2: 0 | K2: 0 | L2: 0 | M2: 0 | N2: 0 | P2: 45.7 | Q2: =A2&"|"&B2&"|"&C2&"|"&D2&"|"&E2&"|"&F2&"|"&G2&"|"&H2&"|"&I2&"|"&J2&"|"&K2&"|"&L2&"|"&M2&"|"&N2&"|"&O2&"|"&P2 | R2: =IF(COUNTIF($Q$2:$Q$1409,Q2)>1,IF(COUNTIF($Q$2:Q2,Q2)=1,"Exact Duplicate - Keep First","Exact Duplicate - Remove"),"Unique")
A3: USR-100002 | B3: 45724 | C3: Control | D3: West | E3: Mobile | F3: Organic | G3: Free | H3: 1 | I3: 0 | J3: 0 | K3: 0 | L3: 0 | M3: 0 | N3: 0 | P3: 48.6 | Q3: =A3&"|"&B3&"|"&C3&"|"&D3&"|"&E3&"|"&F3&"|"&G3&"|"&H3&"|"&I3&"|"&J3&"|"&K3&"|"&L3&"|"&M3&"|"&N3&"|"&O3&"|"&P3 | R3: =IF(COUNTIF($Q$2:$Q$1409,Q3)>1,IF(COUNTIF($Q$2:Q3,Q3)=1,"Exact Duplicate - Keep First","Exact Duplicate - Remove"),"Unique")
A4: USR-100003 | B4: 45771 | C4: Control | D4: East | E4: Mobile | F4: Paid Search | G4: Premium | H4: 1 | I4: 0 | J4: 0 | K4: 0 | L4: 0 | M4: 1 | N4: 0 | P4: 35.4 | Q4: =A4&"|"&B4&"|"&C4&"|"&D4&"|"&E4&"|"&F4&"|"&G4&"|"&H4&"|"&I4&"|"&J4&"|"&K4&"|"&L4&"|"&M4&"|"&N4&"|"&O4&"|"&P4 | R4: =IF(COUNTIF($Q$2:$Q$1409,Q4)>1,IF(COUNTIF($Q$2:Q4,Q4)=1,"Exact Duplicate - Keep First","Exact Duplicate - Remove"),"Unique")
A5: USR-100004 | B5: 45781 | C5: Control | D5: South | E5: Mobile | F5: Email | G5: Basic | H5: 1 | I5: 0 | J5: 0 | K5: 0 | L5: 0 | M5: 0 | N5: 0 | P5: 64.6 | Q5: =A5&"|"&B5&"|"&C5&"|"&D5&"|"&E5&"|"&F5&"|"&G5&"|"&H5&"|"&I5&"|"&J5&"|"&K5&"|"&L5&"|"&M5&"|"&N5&"|"&O5&"|"&P5 | R5: =IF(COUNTIF($Q$2:$Q$1409,Q5)>1,IF(COUNTIF($Q$2:Q5,Q5)=1,"Exact Duplicate - Keep First","Exact Duplicate - Remove"),"Unique")
A6: USR-100005 | B6: 45700 | C6: Control | D6: North | E6: Tablet | F6: Organic | G6: Free | H6: 0 | I6: 0 | J6: 0 | K6: 0 | L6: 0 | M6: 0 | N6: 0 | P6: 66.6 | Q6: =A6&"|"&B6&"|"&C6&"|"&D6&"|"&E6&"|"&F6&"|"&G6&"|"&H6&"|"&I6&"|"&J6&"|"&K6&"|"&L6&"|"&M6&"|"&N6&"|"&O6&"|"&P6 | R6: =IF(COUNTIF($Q$2:$Q$1409,Q6)>1,IF(COUNTIF($Q$2:Q6,Q6)=1,"Exact Duplicate - Keep First","Exact Duplicate - Remove"),"Unique")
A7: USR-100006 | B7: 45685 | C7: Control | D7: East | E7: Mobile | F7: Organic | G7: Premium | H7: 1 | I7: 0 | J7: 0 | K7: 0 | L7: 0 | M7: 0 | N7: 0 | P7: 40.8 | Q7: =A7&"|"&B7&"|"&C7&"|"&D7&"|"&E7&"|"&F7&"|"&G7&"|"&H7&"|"&I7&"|"&J7&"|"&K7&"|"&L7&"|"&M7&"|"&N7&"|"&O7&"|"&P7 | R7: =IF(COUNTIF($Q$2:$Q$1409,Q7)>1,IF(COUNTIF($Q$2:Q7,Q7)=1,"Exact Duplicate - Keep First","Exact Duplicate - Remove"),"Unique")
A8: USR-100007 | B8: 45755 | C8: Control | D8: East | E8: Mobile | F8: Paid Search | G8: Basic | H8: 1 | I8: 1 | J8: 0 | K8: 0 | L8: 0 | M8: 0 | N8: 0 | P8: 57.1 | Q8: =A8&"|"&B8&"|"&C8&"|"&D8&"|"&E8&"|"&F8&"|"&G8&"|"&H8&"|"&I8&"|"&J8&"|"&K8&"|"&L8&"|"&M8&"|"&N8&"|"&O8&"|"&P8 | R8: =IF(COUNTIF($Q$2:$Q$1409,Q8)>1,IF(COUNTIF($Q$2:Q8,Q8)=1,"Exact Duplicate - Keep First","Exact Duplicate - Remove"),"Unique")
A9: USR-100008 | B9: 45794 | C9: Control | D9: South | E9: Mobile | F9: Paid Search | G9: Free | H9: 0 | I9: 0 | J9: 0 | K9: 0 | L9: 0 | M9: 0 | N9: 0 | P9: 36.4 | Q9: =A9&"|"&B9&"|"&C9&"|"&D9&"|"&E9&"|"&F9&"|"&G9&"|"&H9&"|"&I9&"|"&J9&"|"&K9&"|"&L9&"|"&M9&"|"&N9&"|"&O9&"|"&P9 | R9: =IF(COUNTIF($Q$2:$Q$1409,Q9)>1,IF(COUNTIF($Q$2:Q9,Q9)=1,"Exact Duplicate - Keep First","Exact Duplicate - Remove"),"Unique")
A10: USR-100009 | B10: 45711 | C10: Control | D10: South | E10: Tablet | F10: Referral | G10: Basic | H10: 0 | I10: 0 | J10: 0 | K10: 0 | L10: 0 | M10: 0 | N10: 0 | P10: 55.4 | Q10: =A10&"|"&B10&"|"&C10&"|"&D10&"|"&E10&"|"&F10&"|"&G10&"|"&H10&"|"&I10&"|"&J10&"|"&K10&"|"&L10&"|"&M10&"|"&N10&"|"&O10&"|"&P10 | R10: =IF(COUNTIF($Q$2:$Q$1409,Q10)>1,IF(COUNTIF($Q$2:Q10,Q10)=1,"Exact Duplicate - Keep First","Exact Duplicate - Remove"),"Unique")
A11: USR-100010 | B11: 45806 | C11: Control | D11: West | E11: Desktop | F11: Social | G11: Free | H11: 1 | I11: 0 | J11: 0 | K11: 0 | L11: 0 | M11: 0 | N11: 0 | P11: 57.3 | Q11: =A11&"|"&B11&"|"&C11&"|"&D11&"|"&E11&"|"&F11&"|"&G11&"|"&H11&"|"&I11&"|"&J11&"|"&K11&"|"&L11&"|"&M11&"|"&N11&"|"&O11&"|"&P11 | R11: =IF(COUNTIF($Q$2:$Q$1409,Q11)>1,IF(COUNTIF($Q$2:Q11,Q11)=1,"Exact Duplicate - Keep First","Exact Duplicate - Remove"),"Unique")
A12: USR-100011 | B12: 45777 | C12: Control | D12: East | E12: Mobile | F12: Paid Search | G12: Basic | H12: 1 | I12: 1 | J12: 1 | K12: 0 | L12: 0 | M12: 0 | N12: 0 | P12: 63.6 | Q12: =A12&"|"&B12&"|"&C12&"|"&D12&"|"&E12&"|"&F12&"|"&G12&"|"&H12&"|"&I12&"|"&J12&"|"&K12&"|"&L12&"|"&M12&"|"&N12&"|"&O12&"|"&P12 | R12: =IF(COUNTIF($Q$2:$Q$1409,Q12)>1,IF(COUNTIF($Q$2:Q12,Q12)=1,"Exact Duplicate - Keep First","Exact Duplicate - Remove"),"Unique")
A13: USR-100012 | B13: 45732 | C13: Control | D13: East | E13: Mobile | F13: Social | G13: Premium | H13: 1 | I13: 1 | J13: 1 | K13: 0 | L13: 0 | M13: 1 | N13: 0 | P13: 80.4 | Q13: =A13&"|"&B13&"|"&C13&"|"&D13&"|"&E13&"|"&F13&"|"&G13&"|"&H13&"|"&I13&"|"&J13&"|"&K13&"|"&L13&"|"&M13&"|"&N13&"|"&O13&"|"&P13 | R13: =IF(COUNTIF($Q$2:$Q$1409,Q13)>1,IF(COUNTIF($Q$2:Q13,Q13)=1,"Exact Duplicate - Keep First","Exact Duplicate - Remove"),"Unique")
... A60: USR-100059 | B60: 45761 | C60: Control | D60: North | E60: Mobile | F60: Social | G60: Free | H60: 0 | I60: 0 | J60: 0 | K60: 0 | L60: 0 | M60: 2 | N60: 0 | P60: 48.9 | Q60: =A60&"|"&B60&"|"&C60&"|"&D60&"|"&E60&"|"&F60&"|"&G60&"|"&H60&"|"&I60&"|"&J60&"|"&K60&"|"&L60&"|"&M60&"|"&N60&"|"&O60&"|"&P60 | R60: =IF(COUNTIF($Q$2:$Q$1409,Q60)>1,IF(COUNTIF($Q$2:Q60,Q60)=1,"Exact Duplicate - Keep First","Exact Duplicate - Remove"),"Unique")
A61: USR-100060 | B61: 45658 | C61: Control | D61: West | E61: Mobile | F61: Social | G61: Free | H61: 1 | I61: 1 | J61: 1 | K61: 1 | L61: 240.42 | M61: 0 | N61: 0 | O61: 16 | P61: 56.5 | Q61: =A61&"|"&B61&"|"&C61&"|"&D61&"|"&E61&"|"&F61&"|"&G61&"|"&H61&"|"&I61&"|"&J61&"|"&K61&"|"&L61&"|"&M61&"|"&N61&"|"&O61&"|"&P61 | R61: =IF(COUNTIF($Q$2:$Q$1409,Q61)>1,IF(COUNTIF($Q$2:Q61,Q61)=1,"Exact Duplicate - Keep First","Exact Duplicate - Remove"),"Unique")
A62: USR-100061 | B62: 45749 | C62: Control | D62: South | E62: Mobile | F62: Referral | G62: Free | H62: 1 | I62: 0 | J62: 0 | K62: 0 | L62: 0 | M62: 0 | N62: 0 | P62: 53.7 | Q62: =A62&"|"&B62&"|"&C62&"|"&D62&"|"&E62&"|"&F62&"|"&G62&"|"&H62&"|"&I62&"|"&J62&"|"&K62&"|"&L62&"|"&M62&"|"&N62&"|"&O62&"|"&P62 | R62: =IF(COUNTIF($Q$2:$Q$1409,Q62)>1,IF(COUNTIF($Q$2:Q62,Q62)=1,"Exact Duplicate - Keep First","Exact Duplicate - Remove"),"Unique")
A63: USR-100062 | B63: 45745 | C63: Control | D63: North | E63: Mobile | F63: Social | G63: Premium | H63: 0 | I63: 0 | J63: 0 | K63: 0 | L63: 0 | M63: 0 | N63: 0 | P63: 62.2 | Q63: =A63&"|"&B63&"|"&C63&"|"&D63&"|"&E63&"|"&F63&"|"&G63&"|"&H63&"|"&I63&"|"&J63&"|"&K63&"|"&L63&"|"&M63&"|"&N63&"|"&O63&"|"&P63 | R63: =IF(COUNTIF($Q$2:$Q$1409,Q63)>1,IF(COUNTIF($Q$2:Q63,Q63)=1,"Exact Duplicate - Keep First","Exact Duplicate - Remove"),"Unique")
A64: USR-100063 | B64: 45792 | C64: Control | D64: South | E64: Desktop | F64: Organic | G64: Free | H64: 1 | I64: 0 | J64: 0 | K64: 0 | L64: 0 | M64: 0 | N64: 0 | P64: 50.2 | Q64: =A64&"|"&B64&"|"&C64&"|"&D64&"|"&E64&"|"&F64&"|"&G64&"|"&H64&"|"&I64&"|"&J64&"|"&K64&"|"&L64&"|"&M64&"|"&N64&"|"&O64&"|"&P64 | R64: =IF(COUNTIF($Q$2:$Q$1409,Q64)>1,IF(COUNTIF($Q$2:Q64,Q64)=1,"Exact Duplicate - Keep First","Exact Duplicate - Remove"),"Unique")
A65: USR-100064 | B65: 45758 | C65: Control | D65: North | E65: Mobile | F65: Organic | G65: Basic | H65: 1 | I65: 0 | J65: 0 | K65: 0 | L65: 0 | M65: 0 | N65: 0 | P65: 74.3 | Q65: =A65&"|"&B65&"|"&C65&"|"&D65&"|"&E65&"|"&F65&"|"&G65&"|"&H65&"|"&I65&"|"&J65&"|"&K65&"|"&L65&"|"&M65&"|"&N65&"|"&O65&"|"&P65 | R65: =IF(COUNTIF($Q$2:$Q$1409,Q65)>1,IF(COUNTIF($Q$2:Q65,Q65)=1,"Exact Duplicate - Keep First","Exact Duplicate - Remove"),"Unique")
A66: USR-100065 | B66: 45723 | C66: Control | D66: South | E66: Desktop | F66: Paid Search | G66: Free | H66: 1 | I66: 0 | J66: 0 | K66: 0 | L66: 0 | M66: 0 | N66: 0 | P66: 58 | Q66: =A66&"|"&B66&"|"&C66&"|"&D66&"|"&E66&"|"&F66&"|"&G66&"|"&H66&"|"&I66&"|"&J66&"|"&K66&"|"&L66&"|"&M66&"|"&N66&"|"&O66&"|"&P66 | R66: =IF(COUNTIF($Q$2:$Q$1409,Q66)>1,IF(COUNTIF($Q$2:Q66,Q66)=1,"Exact Duplicate - Keep First","Exact Duplicate - Remove"),"Unique")
A67: USR-100066 | B67: 45807 | C67: Control | D67: South | E67: Mobile | F67: Organic | G67: Free | H67: 0 | I67: 0 | J67: 0 | K67: 0 | L67: 0 | M67: 0 | N67: 0 | P67: 46.7 | Q67: =A67&"|"&B67&"|"&C67&"|"&D67&"|"&E67&"|"&F67&"|"&G67&"|"&H67&"|"&I67&"|"&J67&"|"&K67&"|"&L67&"|"&M67&"|"&N67&"|"&O67&"|"&P67 | R67: =IF(COUNTIF($Q$2:$Q$1409,Q67)>1,IF(COUNTIF($Q$2:Q67,Q67)=1,"Exact Duplicate - Keep First","Exact Duplicate - Remove"),"Unique")
A68: USR-100067 | B68: 45664 | C68: Control | D68: South | E68: Desktop | F68: Organic | G68: Premium | H68: 1 | I68: 0 | J68: 0 | K68: 0 | L68: 0 | M68: 1 | N68: 0 | P68: 49.6 | Q68: =A68&"|"&B68&"|"&C68&"|"&D68&"|"&E68&"|"&F68&"|"&G68&"|"&H68&"|"&I68&"|"&J68&"|"&K68&"|"&L68&"|"&M68&"|"&N68&"|"&O68&"|"&P68 | R68: =IF(COUNTIF($Q$2:$Q$1409,Q68)>1,IF(COUNTIF($Q$2:Q68,Q68)=1,"Exact Duplicate - Keep First","Exact Duplicate - Remove"),"Unique")
A69: USR-100068 | B69: 45785 | C69: Control | D69: West | E69: Mobile | F69: Social | G69: Free | H69: 0 | I69: 0 | J69: 0 | K69: 0 | L69: 0 | M69: 0 | N69: 0 | P69: 60.4 | Q69: =A69&"|"&B69&"|"&C69&"|"&D69&"|"&E69&"|"&F69&"|"&G69&"|"&H69&"|"&I69&"|"&J69&"|"&K69&"|"&L69&"|"&M69&"|"&N69&"|"&O69&"|"&P69 | R69: =IF(COUNTIF($Q$2:$Q$1409,Q69)>1,IF(COUNTIF($Q$2:Q69,Q69)=1,"Exact Duplicate - Keep First","Exact Duplicate - Remove"),"Unique")
A70: USR-100069 | B70: 45735 | C70: Control | D70: East | E70: Desktop | F70: Email | G70: Free | H70: 1 | I70: 1 | J70: 1 | K70: 0 | L70: 0 | M70: 0 | N70: 0 | P70: 55.3 | Q70: =A70&"|"&B70&"|"&C70&"|"&D70&"|"&E70&"|"&F70&"|"&G70&"|"&H70&"|"&I70&"|"&J70&"|"&K70&"|"&L70&"|"&M70&"|"&N70&"|"&O70&"|"&P70 | R70: =IF(COUNTIF($Q$2:$Q$1409,Q70)>1,IF(COUNTIF($Q$2:Q70,Q70)=1,"Exact Duplicate - Keep First","Exact Duplicate - Remove"),"Unique")
A71: USR-100070 | B71: 45793 | C71: Control | D71: North | E71: Desktop | F71: Organic | G71: Free | H71: 0 | I71: 0 | J71: 0 | K71: 0 | L71: 0 | M71: 0 | N71: 0 | P71: 56.2 | Q71: =A71&"|"&B71&"|"&C71&"|"&D71&"|"&E71&"|"&F71&"|"&G71&"|"&H71&"|"&I71&"|"&J71&"|"&K71&"|"&L71&"|"&M71&"|"&N71&"|"&O71&"|"&P71 | R71: =IF(COUNTIF($Q$2:$Q$1409,Q71)>1,IF(COUNTIF($Q$2:Q71,Q71)=1,"Exact Duplicate - Keep First","Exact Duplicate - Remove"),"Unique")
A72: USR-100071 | B72: 45724 | C72: Control | D72: West | E72: Mobile | F72: Email | G72: Free | H72: 0 | I72: 0 | J72: 0 | K72: 0 | L72: 0 | M72: 0 | N72: 0 | P72: 29.4 | Q72: =A72&"|"&B72&"|"&C72&"|"&D72&"|"&E72&"|"&F72&"|"&G72&"|"&H72&"|"&I72&"|"&J72&"|"&K72&"|"&L72&"|"&M72&"|"&N72&"|"&O72&"|"&P72 | R72: =IF(COUNTIF($Q$2:$Q$1409,Q72)>1,IF(COUNTIF($Q$2:Q72,Q72)=1,"Exact Duplicate - Keep First","Exact Duplicate - Remove"),"Unique")
A73: USR-100072 | B73: 45724 | C73: Control | D73: East | E73: Mobile | F73: Email | G73: Free | H73: 1 | I73: 0 | J73: 0 | K73: 0 | L73: 0 | M73: 0 | N73: 0 | P73: 54.2 | Q73: =A73&"|"&B73&"|"&C73&"|"&D73&"|"&E73&"|"&F73&"|"&G73&"|"&H73&"|"&I73&"|"&J73&"|"&K73&"|"&L73&"|"&M73&"|"&N73&"|"&O73&"|"&P73 | R73: =IF(COUNTIF($Q$2:$Q$1409,Q73)>1,IF(COUNTIF($Q$2:Q73,Q73)=1,"Exact Duplicate - Keep First","Exact Duplicate - Remove"),"Unique")
... A79: USR-100078 | B79: 45673 | C79: Control | D79: North | E79: Mobile | F79: Organic | G79: Free | H79: 0 | I79: 0 | J79: 0 | K79: 0 | L79: 0 | M79: 2 | N79: 0 | P79: 48.4 | Q79: =A79&"|"&B79&"|"&C79&"|"&D79&"|"&E79&"|"&F79&"|"&G79&"|"&H79&"|"&I79&"|"&J79&"|"&K79&"|"&L79&"|"&M79&"|"&N79&"|"&O79&"|"&P79 | R79: =IF(COUNTIF($Q$2:$Q$1409,Q79)>1,IF(COUNTIF($Q$2:Q79,Q79)=1,"Exact Duplicate - Keep First","Exact Duplicate - Remove"),"Unique")
A80: USR-100079 | B80: 45708 | C80: Control | D80: West | E80: Desktop | F80: Organic | G80: Free | H80: 1 | I80: 1 | J80: 1 | K80: 1 | L80: 457.51 | M80: 0 | N80: 0 | O80: 7 | P80: 38 | Q80: =A80&"|"&B80&"|"&C80&"|"&D80&"|"&E80&"|"&F80&"|"&G80&"|"&H80&"|"&I80&"|"&J80&"|"&K80&"|"&L80&"|"&M80&"|"&N80&"|"&O80&"|"&P80 | R80: =IF(COUNTIF($Q$2:$Q$1409,Q80)>1,IF(COUNTIF($Q$2:Q80,Q80)=1,"Exact Duplicate - Keep First","Exact Duplicate - Remove"),"Unique")
A81: USR-100080 | B81: 45798 | C81: Control | D81: East | E81: Mobile | F81: Social | G81: Free | H81: 1 | I81: 0 | J81: 0 | K81: 0 | L81: 0 | M81: 0 | N81: 0 | P81: 44.2 | Q81: =A81&"|"&B81&"|"&C81&"|"&D81&"|"&E81&"|"&F81&"|"&G81&"|"&H81&"|"&I81&"|"&J81&"|"&K81&"|"&L81&"|"&M81&"|"&N81&"|"&O81&"|"&P81 | R81: =IF(COUNTIF($Q$2:$Q$1409,Q81)>1,IF(COUNTIF($Q$2:Q81,Q81)=1,"Exact Duplicate - Keep First","Exact Duplicate - Remove"),"Unique")
A82: USR-100081 | B82: 45785 | C82: Control | D82: South | E82: Mobile | F82: Organic | G82: Free | H82: 1 | I82: 1 | J82: 1 | K82: 0 | L82: 0 | M82: 0 | N82: 0 | P82: 81.2 | Q82: =A82&"|"&B82&"|"&C82&"|"&D82&"|"&E82&"|"&F82&"|"&G82&"|"&H82&"|"&I82&"|"&J82&"|"&K82&"|"&L82&"|"&M82&"|"&N82&"|"&O82&"|"&P82 | R82: =IF(COUNTIF($Q$2:$Q$1409,Q82)>1,IF(COUNTIF($Q$2:Q82,Q82)=1,"Exact Duplicate - Keep First","Exact Duplicate - Remove"),"Unique")
A83: USR-100082 | B83: 45724 | C83: Control | D83: South | E83: Mobile | F83: Referral | G83: Free | H83: 1 | I83: 1 | J83: 0 | K83: 0 | L83: 0 | M83: 0 | N83: 0 | P83: 63.8 | Q83: =A83&"|"&B83&"|"&C83&"|"&D83&"|"&E83&"|"&F83&"|"&G83&"|"&H83&"|"&I83&"|"&J83&"|"&K83&"|"&L83&"|"&M83&"|"&N83&"|"&O83&"|"&P83 | R83: =IF(COUNTIF($Q$2:$Q$1409,Q83)>1,IF(COUNTIF($Q$2:Q83,Q83)=1,"Exact Duplicate - Keep First","Exact Duplicate - Remove"),"Unique")
A84: USR-100083 | B84: 45748 | C84: Control | D84: South | E84: Desktop | F84: Email | G84: Free | H84: 0 | I84: 0 | J84: 0 | K84: 0 | L84: 0 | M84: 0 | N84: 0 | P84: 64.7 | Q84: =A84&"|"&B84&"|"&C84&"|"&D84&"|"&E84&"|"&F84&"|"&G84&"|"&H84&"|"&I84&"|"&J84&"|"&K84&"|"&L84&"|"&M84&"|"&N84&"|"&O84&"|"&P84 | R84: =IF(COUNTIF($Q$2:$Q$1409,Q84)>1,IF(COUNTIF($Q$2:Q84,Q84)=1,"Exact Duplicate - Keep First","Exact Duplicate - Remove"),"Unique")
A85: USR-100084 | B85: 45719 | C85: Control | D85: West | E85: Mobile | F85: Social | G85: Basic | H85: 0 | I85: 0 | J85: 0 | K85: 0 | L85: 0 | M85: 0 | N85: 0 | P85: 60.4 | Q85: =A85&"|"&B85&"|"&C85&"|"&D85&"|"&E85&"|"&F85&"|"&G85&"|"&H85&"|"&I85&"|"&J85&"|"&K85&"|"&L85&"|"&M85&"|"&N85&"|"&O85&"|"&P85 | R85: =IF(COUNTIF($Q$2:$Q$1409,Q85)>1,IF(COUNTIF($Q$2:Q85,Q85)=1,"Exact Duplicate - Keep First","Exact Duplicate - Remove"),"Unique")
A86: USR-100085 | B86: 45763 | C86: Control | D86: South | E86: Mobile | F86: Paid Search | G86: Free | H86: 0 | I86: 0 | J86: 0 | K86: 0 | L86: 0 | M86: 0 | N86: 0 | P86: 66.6 | Q86: =A86&"|"&B86&"|"&C86&"|"&D86&"|"&E86&"|"&F86&"|"&G86&"|"&H86&"|"&I86&"|"&J86&"|"&K86&"|"&L86&"|"&M86&"|"&N86&"|"&O86&"|"&P86 | R86: =IF(COUNTIF($Q$2:$Q$1409,Q86)>1,IF(COUNTIF($Q$2:Q86,Q86)=1,"Exact Duplicate - Keep First","Exact Duplicate - Remove"),"Unique")
A87: USR-100086 | B87: 45666 | C87: Control | D87: North | E87: Desktop | F87: Organic | G87: Free | H87: 1 | I87: 0 | J87: 0 | K87: 0 | L87: 0 | M87: 0 | N87: 0 | P87: 50.9 | Q87: =A87&"|"&B87&"|"&C87&"|"&D87&"|"&E87&"|"&F87&"|"&G87&"|"&H87&"|"&I87&"|"&J87&"|"&K87&"|"&L87&"|"&M87&"|"&N87&"|"&O87&"|"&P87 | R87: =IF(COUNTIF($Q$2:$Q$1409,Q87)>1,IF(COUNTIF($Q$2:Q87,Q87)=1,"Exact Duplicate - Keep First","Exact Duplicate - Remove"),"Unique")
A88: USR-100087 | B88: 45679 | C88: Control | D88: West | E88: Desktop | F88: Social | G88: Basic | H88: 0 | I88: 0 | J88: 0 | K88: 0 | L88: 0 | M88: 0 | N88: 0 | P88: 51 | Q88: =A88&"|"&B88&"|"&C88&"|"&D88&"|"&E88&"|"&F88&"|"&G88&"|"&H88&"|"&I88&"|"&J88&"|"&K88&"|"&L88&"|"&M88&"|"&N88&"|"&O88&"|"&P88 | R88: =IF(COUNTIF($Q$2:$Q$1409,Q88)>1,IF(COUNTIF($Q$2:Q88,Q88)=1,"Exact Duplicate - Keep First","Exact Duplicate - Remove"),"Unique")
A89: USR-100088 | B89: 45777 | C89: Control | D89: South | E89: Mobile | F89: Email | G89: Premium | H89: 0 | I89: 0 | J89: 0 | K89: 0 | L89: 0 | M89: 0 | N89: 0 | P89: 65.8 | Q89: =A89&"|"&B89&"|"&C89&"|"&D89&"|"&E89&"|"&F89&"|"&G89&"|"&H89&"|"&I89&"|"&J89&"|"&K89&"|"&L89&"|"&M89&"|"&N89&"|"&O89&"|"&P89 | R89: =IF(COUNTIF($Q$2:$Q$1409,Q89)>1,IF(COUNTIF($Q$2:Q89,Q89)=1,"Exact Duplicate - Keep First","Exact Duplicate - Remove"),"Unique")
A90: USR-100089 | B90: 45772 | C90: Control | D90: North | E90: Mobile | F90: Referral | G90: Basic | H90: 1 | I90: 0 | J90: 0 | K90: 0 | L90: 0 | M90: 0 | N90: 0 | P90: 61.8 | Q90: =A90&"|"&B90&"|"&C90&"|"&D90&"|"&E90&"|"&F90&"|"&G90&"|"&H90&"|"&I90&"|"&J90&"|"&K90&"|"&L90&"|"&M90&"|"&N90&"|"&O90&"|"&P90 | R90: =IF(COUNTIF($Q$2:$Q$1409,Q90)>1,IF(COUNTIF($Q$2:Q90,Q90)=1,"Exact Duplicate - Keep First","Exact Duplicate - Remove"),"Unique")
A91: USR-100090 | B91: 45689 | C91: Control | D91: North | E91: Mobile | F91: Organic | G91: Basic | H91: 1 | I91: 0 | J91: 0 | K91: 0 | L91: 0 | M91: 0 | N91: 0 | P91: 54.5 | Q91: =A91&"|"&B91&"|"&C91&"|"&D91&"|"&E91&"|"&F91&"|"&G91&"|"&H91&"|"&I91&"|"&J91&"|"&K91&"|"&L91&"|"&M91&"|"&N91&"|"&O91&"|"&P91 | R91: =IF(COUNTIF($Q$2:$Q$1409,Q91)>1,IF(COUNTIF($Q$2:Q91,Q91)=1,"Exact Duplicate - Keep First","Exact Duplicate - Remove"),"Unique")
...

Sheet data_quality_checks
A1: Data Quality Checks – Campaign Experiment Data
A3: 1. Missing Value Summary
A4: Column | B4: Total Rows | C4: Missing Count | D4: % Missing
A5: user_id | B5: =COUNTA(raw_data!A$2:A$1409)+COUNTBLANK(raw_data!A$2:A$1409) | C5: =COUNTBLANK(raw_data!A$2:A$1409) | D5: =C5/B5
A6: signup_date | B6: =COUNTA(raw_data!B$2:B$1409)+COUNTBLANK(raw_data!B$2:B$1409) | C6: =COUNTBLANK(raw_data!B$2:B$1409) | D6: =C6/B6
A7: experiment_group | B7: =COUNTA(raw_data!C$2:C$1409)+COUNTBLANK(raw_data!C$2:C$1409) | C7: =COUNTBLANK(raw_data!C$2:C$1409) | D7: =C7/B7
A8: region | B8: =COUNTA(raw_data!D$2:D$1409)+COUNTBLANK(raw_data!D$2:D$1409) | C8: =COUNTBLANK(raw_data!D$2:D$1409) | D8: =C8/B8
A9: device_type | B9: =COUNTA(raw_data!E$2:E$1409)+COUNTBLANK(raw_data!E$2:E$1409) | C9: =COUNTBLANK(raw_data!E$2:E$1409) | D9: =C9/B9
A10: traffic_source | B10: =COUNTA(raw_data!F$2:F$1409)+COUNTBLANK(raw_data!F$2:F$1409) | C10: =COUNTBLANK(raw_data!F$2:F$1409) | D10: =C10/B10
A11: plan_type | B11: =COUNTA(raw_data!G$2:G$1409)+COUNTBLANK(raw_data!G$2:G$1409) | C11: =COUNTBLANK(raw_data!G$2:G$1409) | D11: =C11/B11
A12: visited_landing_page | B12: =COUNTA(raw_data!H$2:H$1409)+COUNTBLANK(raw_data!H$2:H$1409) | C12: =COUNTBLANK(raw_data!H$2:H$1409) | D12: =C12/B12
A13: started_trial | B13: =COUNTA(raw_data!I$2:I$1409)+COUNTBLANK(raw_data!I$2:I$1409) | C13: =COUNTBLANK(raw_data!I$2:I$1409) | D13: =C13/B13
A14: completed_onboarding | B14: =COUNTA(raw_data!J$2:J$1409)+COUNTBLANK(raw_data!J$2:J$1409) | C14: =COUNTBLANK(raw_data!J$2:J$1409) | D14: =C14/B14
A15: converted_to_paid | B15: =COUNTA(raw_data!K$2:K$1409)+COUNTBLANK(raw_data!K$2:K$1409) | C15: =COUNTBLANK(raw_data!K$2:K$1409) | D15: =C15/B15
A16: revenue_30d | B16: =COUNTA(raw_data!L$2:L$1409)+COUNTBLANK(raw_data!L$2:L$1409) | C16: =COUNTBLANK(raw_data!L$2:L$1409) | D16: =C16/B16
A17: support_tickets_30d | B17: =COUNTA(raw_data!M$2:M$1409)+COUNTBLANK(raw_data!M$2:M$1409) | C17: =COUNTBLANK(raw_data!M$2:M$1409) | D17: =C17/B17
A18: refund_requested | B18: =COUNTA(raw_data!N$2:N$1409)+COUNTBLANK(raw_data!N$2:N$1409) | C18: =COUNTBLANK(raw_data!N$2:N$1409) | D18: =C18/B18
A19: days_to_convert | B19: =COUNTA(raw_data!O$2:O$1409)+COUNTBLANK(raw_data!O$2:O$1409) | C19: =COUNTBLANK(raw_data!O$2:O$1409) | D19: =C19/B19
A20: engagement_score | B20: =COUNTA(raw_data!P$2:P$1409)+COUNTBLANK(raw_data!P$2:P$1409) | C20: =COUNTBLANK(raw_data!P$2:P$1409) | D20: =C20/B20
A22: 2. Duplicate Checks
A23: Total raw rows | B23: =COUNTA(raw_data!A2:A1409)
A24: Distinct user_ids | B24: =SUMPRODUCT(1/COUNTIF(raw_data!A2:A1409,raw_data!A2:A1409))
A25: Duplicate user_id rows (extra occurrences) | B25: =B23-B24
A27: 3. Invalid Binary Value Checks (should only contain 0/1)
A28: Column | B28: Invalid (not 0 or 1) count
A29: visited_landing_page | B29: =SUMPRODUCT((raw_data!H2:H1409<>0)*(raw_data!H2:H1409<>1))
A30: started_trial | B30: =SUMPRODUCT((raw_data!I2:I1409<>0)*(raw_data!I2:I1409<>1))
A31: completed_onboarding | B31: =SUMPRODUCT((raw_data!J2:J1409<>0)*(raw_data!J2:J1409<>1))
A32: converted_to_paid | B32: =SUMPRODUCT((raw_data!K2:K1409<>0)*(raw_data!K2:K1409<>1))
A33: refund_requested | B33: =SUMPRODUCT((raw_data!N2:N1409<>0)*(raw_data!N2:N1409<>1))
A35: 4. Group Counts
A36: Control (raw, incl. duplicates) | B36: =COUNTIF(raw_data!C2:C1409,"Control")
A37: Treatment (raw, incl. duplicates) | B37: =COUNTIF(raw_data!C2:C1409,"Treatment")
A39: 5. Revenue Outlier Check (converted users, IQR method)
A40: Q1 revenue (converted users) | B40: =QUARTILE(IF(raw_data!K2:K1409=1,raw_data!L2:L1409),1)
A41: Q3 revenue (converted users) | B41: =QUARTILE(IF(raw_data!K2:K1409=1,raw_data!L2:L1409),3)
A42: IQR Upper Bound (Q3 + 1.5*IQR) | B42: =B41+1.5*(B41-B40)
A43: Count of converted users above upper bound (flagged as outliers) | B43: =SUMPRODUCT((raw_data!K2:K1409=1)*(raw_data!L2:L1409>B42))
A45: 6. Segment Distribution Across Groups (counts)
A46: -- region --
...

Sheet cleaned_data
A1: user_id | B1: signup_date | C1: experiment_group | D1: region | E1: device_type | F1: traffic_source | G1: plan_type | H1: visited_landing_page | I1: started_trial | J1: completed_onboarding | K1: converted_to_paid | L1: revenue_30d | M1: support_tickets_30d | N1: refund_requested | O1: days_to_convert | P1: engagement_score
A2: USR-100001 | B2: 45732 | C2: Control | D2: North | E2: Desktop | F2: Email | G2: Basic | H2: 0 | I2: 0 | J2: 0 | K2: 0 | L2: 0 | M2: 0 | N2: 0 | P2: 45.7
A3: USR-100002 | B3: 45724 | C3: Control | D3: West | E3: Mobile | F3: Organic | G3: Free | H3: 1 | I3: 0 | J3: 0 | K3: 0 | L3: 0 | M3: 0 | N3: 0 | P3: 48.6
A4: USR-100003 | B4: 45771 | C4: Control | D4: East | E4: Mobile | F4: Paid Search | G4: Premium | H4: 1 | I4: 0 | J4: 0 | K4: 0 | L4: 0 | M4: 1 | N4: 0 | P4: 35.4
A5: USR-100004 | B5: 45781 | C5: Control | D5: South | E5: Mobile | F5: Email | G5: Basic | H5: 1 | I5: 0 | J5: 0 | K5: 0 | L5: 0 | M5: 0 | N5: 0 | P5: 64.6
A6: USR-100005 | B6: 45700 | C6: Control | D6: North | E6: Tablet | F6: Organic | G6: Free | H6: 0 | I6: 0 | J6: 0 | K6: 0 | L6: 0 | M6: 0 | N6: 0 | P6: 66.6
A7: USR-100006 | B7: 45685 | C7: Control | D7: East | E7: Mobile | F7: Organic | G7: Premium | H7: 1 | I7: 0 | J7: 0 | K7: 0 | L7: 0 | M7: 0 | N7: 0 | P7: 40.8
A8: USR-100007 | B8: 45755 | C8: Control | D8: East | E8: Mobile | F8: Paid Search | G8: Basic | H8: 1 | I8: 1 | J8: 0 | K8: 0 | L8: 0 | M8: 0 | N8: 0 | P8: 57.1
A9: USR-100008 | B9: 45794 | C9: Control | D9: South | E9: Mobile | F9: Paid Search | G9: Free | H9: 0 | I9: 0 | J9: 0 | K9: 0 | L9: 0 | M9: 0 | N9: 0 | P9: 36.4
A10: USR-100009 | B10: 45711 | C10: Control | D10: South | E10: Tablet | F10: Referral | G10: Basic | H10: 0 | I10: 0 | J10: 0 | K10: 0 | L10: 0 | M10: 0 | N10: 0 | P10: 55.4
A11: USR-100010 | B11: 45806 | C11: Control | D11: West | E11: Desktop | F11: Social | G11: Free | H11: 1 | I11: 0 | J11: 0 | K11: 0 | L11: 0 | M11: 0 | N11: 0 | P11: 57.3
A12: USR-100011 | B12: 45777 | C12: Control | D12: East | E12: Mobile | F12: Paid Search | G12: Basic | H12: 1 | I12: 1 | J12: 1 | K12: 0 | L12: 0 | M12: 0 | N12: 0 | P12: 63.6
A13: USR-100012 | B13: 45732 | C13: Control | D13: East | E13: Mobile | F13: Social | G13: Premium | H13: 1 | I13: 1 | J13: 1 | K13: 0 | L13: 0 | M13: 1 | N13: 0 | P13: 80.4
... A60: USR-100059 | B60: 45761 | C60: Control | D60: North | E60: Mobile | F60: Social | G60: Free | H60: 0 | I60: 0 | J60: 0 | K60: 0 | L60: 0 | M60: 2 | N60: 0 | P60: 48.9
A61: USR-100060 | B61: 45658 | C61: Control | D61: West | E61: Mobile | F61: Social | G61: Free | H61: 1 | I61: 1 | J61: 1 | K61: 1 | L61: 240.42 | M61: 0 | N61: 0 | O61: 16 | P61: 56.5
A62: USR-100061 | B62: 45749 | C62: Control | D62: South | E62: Mobile | F62: Referral | G62: Free | H62: 1 | I62: 0 | J62: 0 | K62: 0 | L62: 0 | M62: 0 | N62: 0 | P62: 53.7
A63: USR-100062 | B63: 45745 | C63: Control | D63: North | E63: Mobile | F63: Social | G63: Premium | H63: 0 | I63: 0 | J63: 0 | K63: 0 | L63: 0 | M63: 0 | N63: 0 | P63: 62.2
A64: USR-100063 | B64: 45792 | C64: Control | D64: South | E64: Desktop | F64: Organic | G64: Free | H64: 1 | I64: 0 | J64: 0 | K64: 0 | L64: 0 | M64: 0 | N64: 0 | P64: 50.2
A65: USR-100064 | B65: 45758 | C65: Control | D65: North | E65: Mobile | F65: Organic | G65: Basic | H65: 1 | I65: 0 | J65: 0 | K65: 0 | L65: 0 | M65: 0 | N65: 0 | P65: 74.3
A66: USR-100065 | B66: 45723 | C66: Control | D66: South | E66: Desktop | F66: Paid Search | G66: Free | H66: 1 | I66: 0 | J66: 0 | K66: 0 | L66: 0 | M66: 0 | N66: 0 | P66: 58
A67: USR-100066 | B67: 45807 | C67: Control | D67: South | E67: Mobile | F67: Organic | G67: Free | H67: 0 | I67: 0 | J67: 0 | K67: 0 | L67: 0 | M67: 0 | N67: 0 | P67: 46.7
A68: USR-100067 | B68: 45664 | C68: Control | D68: South | E68: Desktop | F68: Organic | G68: Premium | H68: 1 | I68: 0 | J68: 0 | K68: 0 | L68: 0 | M68: 1 | N68: 0 | P68: 49.6
A69: USR-100068 | B69: 45785 | C69: Control | D69: West | E69: Mobile | F69: Social | G69: Free | H69: 0 | I69: 0 | J69: 0 | K69: 0 | L69: 0 | M69: 0 | N69: 0 | P69: 60.4
A70: USR-100069 | B70: 45735 | C70: Control | D70: East | E70: Desktop | F70: Email | G70: Free | H70: 1 | I70: 1 | J70: 1 | K70: 0 | L70: 0 | M70: 0 | N70: 0 | P70: 55.3
A71: USR-100070 | B71: 45793 | C71: Control | D71: North | E71: Desktop | F71: Organic | G71: Free | H71: 0 | I71: 0 | J71: 0 | K71: 0 | L71: 0 | M71: 0 | N71: 0 | P71: 56.2
A72: USR-100071 | B72: 45724 | C72: Control | D72: West | E72: Mobile | F72: Email | G72: Free | H72: 0 | I72: 0 | J72: 0 | K72: 0 | L72: 0 | M72: 0 | N72: 0 | P72: 29.4
A73: USR-100072 | B73: 45724 | C73: Control | D73: East | E73: Mobile | F73: Email | G73: Free | H73: 1 | I73: 0 | J73: 0 | K73: 0 | L73: 0 | M73: 0 | N73: 0 | P73: 54.2
... A79: USR-100078 | B79: 45673 | C79: Control | D79: North | E79: Mobile | F79: Organic | G79: Free | H79: 0 | I79: 0 | J79: 0 | K79: 0 | L79: 0 | M79: 2 | N79: 0 | P79: 48.4
A80: USR-100079 | B80: 45708 | C80: Control | D80: West | E80: Desktop | F80: Organic | G80: Free | H80: 1 | I80: 1 | J80: 1 | K80: 1 | L80: 457.51 | M80: 0 | N80: 0 | O80: 7 | P80: 38
A81: USR-100080 | B81: 45798 | C81: Control | D81: East | E81: Mobile | F81: Social | G81: Free | H81: 1 | I81: 0 | J81: 0 | K81: 0 | L81: 0 | M81: 0 | N81: 0 | P81: 44.2
A82: USR-100081 | B82: 45785 | C82: Control | D82: South | E82: Mobile | F82: Organic | G82: Free | H82: 1 | I82: 1 | J82: 1 | K82: 0 | L82: 0 | M82: 0 | N82: 0 | P82: 81.2
A83: USR-100082 | B83: 45724 | C83: Control | D83: South | E83: Mobile | F83: Referral | G83: Free | H83: 1 | I83: 1 | J83: 0 | K83: 0 | L83: 0 | M83: 0 | N83: 0 | P83: 63.8
A84: USR-100083 | B84: 45748 | C84: Control | D84: South | E84: Desktop | F84: Email | G84: Free | H84: 0 | I84: 0 | J84: 0 | K84: 0 | L84: 0 | M84: 0 | N84: 0 | P84: 64.7
A85: USR-100084 | B85: 45719 | C85: Control | D85: West | E85: Mobile | F85: Social | G85: Basic | H85: 0 | I85: 0 | J85: 0 | K85: 0 | L85: 0 | M85: 0 | N85: 0 | P85: 60.4
A86: USR-100085 | B86: 45763 | C86: Control | D86: South | E86: Mobile | F86: Paid Search | G86: Free | H86: 0 | I86: 0 | J86: 0 | K86: 0 | L86: 0 | M86: 0 | N86: 0 | P86: 66.6
A87: USR-100086 | B87: 45666 | C87: Control | D87: North | E87: Desktop | F87: Organic | G87: Free | H87: 1 | I87: 0 | J87: 0 | K87: 0 | L87: 0 | M87: 0 | N87: 0 | P87: 50.9
A88: USR-100087 | B88: 45679 | C88: Control | D88: West | E88: Desktop | F88: Social | G88: Basic | H88: 0 | I88: 0 | J88: 0 | K88: 0 | L88: 0 | M88: 0 | N88: 0 | P88: 51
A89: USR-100088 | B89: 45777 | C89: Control | D89: South | E89: Mobile | F89: Email | G89: Premium | H89: 0 | I89: 0 | J89: 0 | K89: 0 | L89: 0 | M89: 0 | N89: 0 | P89: 65.8
A90: USR-100089 | B90: 45772 | C90: Control | D90: North | E90: Mobile | F90: Referral | G90: Basic | H90: 1 | I90: 0 | J90: 0 | K90: 0 | L90: 0 | M90: 0 | N90: 0 | P90: 61.8
A91: USR-100090 | B91: 45689 | C91: Control | D91: North | E91: Mobile | F91: Organic | G91: Basic | H91: 1 | I91: 0 | J91: 0 | K91: 0 | L91: 0 | M91: 0 | N91: 0 | P91: 54.5
...
